[2024-05-24T00:21:37.488+0000] {local_task_job_runner.py:120} INFO - ::group::Pre task execution logs
[2024-05-24T00:21:37.498+0000] {taskinstance.py:2076} INFO - Dependencies all met for dep_context=non-requeueable deps ti=<TaskInstance: data_pipeline.load_Solar_Flare_Data manual__2024-05-24T00:21:33.579269+00:00 [queued]>
[2024-05-24T00:21:37.503+0000] {taskinstance.py:2076} INFO - Dependencies all met for dep_context=requeueable deps ti=<TaskInstance: data_pipeline.load_Solar_Flare_Data manual__2024-05-24T00:21:33.579269+00:00 [queued]>
[2024-05-24T00:21:37.503+0000] {taskinstance.py:2306} INFO - Starting attempt 1 of 1
[2024-05-24T00:21:37.510+0000] {taskinstance.py:2330} INFO - Executing <Task(PythonOperator): load_Solar_Flare_Data> on 2024-05-24 00:21:33.579269+00:00
[2024-05-24T00:21:37.514+0000] {warnings.py:110} WARNING - /home/***/.local/lib/python3.12/site-packages/***/task/task_runner/standard_task_runner.py:61: DeprecationWarning: This process (pid=259) is multi-threaded, use of fork() may lead to deadlocks in the child.
  pid = os.fork()

[2024-05-24T00:21:37.515+0000] {standard_task_runner.py:63} INFO - Started process 267 to run task
[2024-05-24T00:21:37.515+0000] {standard_task_runner.py:90} INFO - Running: ['***', 'tasks', 'run', 'data_pipeline', 'load_Solar_Flare_Data', 'manual__2024-05-24T00:21:33.579269+00:00', '--job-id', '38', '--raw', '--subdir', 'DAGS_FOLDER/***_dag.py', '--cfg-path', '/tmp/tmp7je18ley']
[2024-05-24T00:21:37.516+0000] {standard_task_runner.py:91} INFO - Job 38: Subtask load_Solar_Flare_Data
[2024-05-24T00:21:37.538+0000] {task_command.py:426} INFO - Running <TaskInstance: data_pipeline.load_Solar_Flare_Data manual__2024-05-24T00:21:33.579269+00:00 [running]> on host 7f18484bb9a3
[2024-05-24T00:21:37.589+0000] {taskinstance.py:2648} INFO - Exporting env vars: AIRFLOW_CTX_DAG_OWNER='***' AIRFLOW_CTX_DAG_ID='data_pipeline' AIRFLOW_CTX_TASK_ID='load_Solar_Flare_Data' AIRFLOW_CTX_EXECUTION_DATE='2024-05-24T00:21:33.579269+00:00' AIRFLOW_CTX_TRY_NUMBER='1' AIRFLOW_CTX_DAG_RUN_ID='manual__2024-05-24T00:21:33.579269+00:00'
[2024-05-24T00:21:37.590+0000] {taskinstance.py:430} INFO - ::endgroup::
[2024-05-24T00:21:37.590+0000] {log.py:232} WARNING - [2024-05-24 00:21:37,590] [INFO] - Database CombinedDataset.sqlite exists. Connected successfully.
[2024-05-24T00:21:37.590+0000] {base_logger.py:19} INFO - Database CombinedDataset.sqlite exists. Connected successfully.
[2024-05-24T00:21:37.621+0000] {log.py:232} WARNING - [2024-05-24 00:21:37,621] [ERROR] - An exception occurred: table "Solar_Flare_Data" already exists
[2024-05-24T00:21:37.621+0000] {base_logger.py:25} ERROR - An exception occurred: table "Solar_Flare_Data" already exists
[2024-05-24T00:21:37.622+0000] {log.py:232} WARNING - [2024-05-24 00:21:37,622] [INFO] - Connection to CombinedDataset.sqlite closed.
[2024-05-24T00:21:37.622+0000] {base_logger.py:19} INFO - Connection to CombinedDataset.sqlite closed.
[2024-05-24T00:21:37.622+0000] {python.py:237} INFO - Done. Returned value was: None
[2024-05-24T00:21:37.622+0000] {taskinstance.py:441} INFO - ::group::Post task execution logs
[2024-05-24T00:21:37.627+0000] {taskinstance.py:1206} INFO - Marking task as SUCCESS. dag_id=data_pipeline, task_id=load_Solar_Flare_Data, run_id=manual__2024-05-24T00:21:33.579269+00:00, execution_date=20240524T002133, start_date=20240524T002137, end_date=20240524T002137
[2024-05-24T00:21:37.648+0000] {local_task_job_runner.py:240} INFO - Task exited with return code 0
[2024-05-24T00:21:37.655+0000] {taskinstance.py:3498} INFO - 0 downstream tasks scheduled from follow-on schedule check
[2024-05-24T00:21:37.655+0000] {local_task_job_runner.py:222} INFO - ::endgroup::
